thats this?
[18:44:43] Error fetching portfolio data: ('Connection aborted.', ConnectionResetError(10054, 'An existing connection was forcibly closed by the remote host', None, 10054, None))
[18:44:43] Traceback: Traceback (most recent call last): File "C:\Users\Admin\AppData\Local\Packages\PythonSoftwareFoundation.Python.3.10_qbz5n2kfra8p0\LocalCache\local-packages\Python310\site-packages\urllib3\connectionpool.py", line 716, in urlopen httplib_response = self._make_request( File "C:\Users\Admin\AppData\Local\Packages\PythonSoftwareFoundation.Python.3.10_qbz5n2kfra8p0\LocalCache\local-packages\Python310\site-packages\urllib3\connectionpool.py", line 404, in _make_request self._validate_conn(conn) File "C:\Users\Admin\AppData\Local\Packages\PythonSoftwareFoundation.Python.3.10_qbz5n2kfra8p0\LocalCache\local-packages\Python310\site-packages\urllib3\connectionpool.py", line 1061, in _validate_conn conn.connect() File "C:\Users\Admin\AppData\Local\Packages\PythonSoftwareFoundation.Python.3.10_qbz5n2kfra8p0\LocalCache\local-packages\Python310\site-packages\urllib3\connection.py", line 419, in connect self.sock = ssl_wrap_socket( File "C:\Users\Admin\AppData\Local\Packages\PythonSoftwareFoundation.Python.3.10_qbz5n2kfra8p0\LocalCache\local-packages\Python310\site-packages\urllib3\util\ssl_.py", line 458, in ssl_wrap_socket ssl_sock = _ssl_wrap_socket_impl( File "C:\Users\Admin\AppData\Local\Packages\PythonSoftwareFoundation.Python.3.10_qbz5n2kfra8p0\LocalCache\local-packages\Python310\site-packages\urllib3\util\ssl_.py", line 502, in _ssl_wrap_socket_impl return ssl_context.wrap_socket(sock, server_hostname=server_hostname) File "C:\Program Files\WindowsApps\PythonSoftwareFoundation.Python.3.10_3.10.3056.0_x64__qbz5n2kfra8p0\lib\ssl.py", line 513, in wrap_socket return self.sslsocket_class._create( File "C:\Program Files\WindowsApps\PythonSoftwareFoundation.Python.3.10_3.10.3056.0_x64__qbz5n2kfra8p0\lib\ssl.py", line 1071, in _create self.do_handshake() File "C:\Program Files\WindowsApps\PythonSoftwareFoundation.Python.3.10_3.10.3056.0_x64__qbz5n2kfra8p0\lib\ssl.py", line 1342, in do_handshake self._sslobj.do_handshake() ConnectionResetError: [WinError 10054] An existing connection was forcibly closed by the remote host During handling of the above exception, another exception occurred: Traceback (most recent call last): File "C:\Users\Admin\AppData\Local\Packages\PythonSoftwareFoundation.Python.3.10_qbz5n2kfra8p0\LocalCache\local-packages\Python310\site-packages\requests\adapters.py", line 486, in send resp = conn.urlopen( File "C:\Users\Admin\AppData\Local\Packages\PythonSoftwareFoundation.Python.3.10_qbz5n2kfra8p0\LocalCache\local-packages\Python310\site-packages\urllib3\connectionpool.py", line 802, in urlopen retries = retries.increment( File "C:\Users\Admin\AppData\Local\Packages\PythonSoftwareFoundation.Python.3.10_qbz5n2kfra8p0\LocalCache\local-packages\Python310\site-packages\urllib3\util\retry.py", line 552, in increment raise six.reraise(type(error), error, _stacktrace) File "C:\Users\Admin\AppData\Local\Packages\PythonSoftwareFoundation.Python.3.10_qbz5n2kfra8p0\LocalCache\local-packages\Python310\site-packages\urllib3\packages\six.py", line 769, in reraise raise value.with_traceback(tb) File "C:\Users\Admin\AppData\Local\Packages\PythonSoftwareFoundation.Python.3.10_qbz5n2kfra8p0\LocalCache\local-packages\Python310\site-packages\urllib3\connectionpool.py", line 716, in urlopen httplib_response = self._make_request( File "C:\Users\Admin\AppData\Local\Packages\PythonSoftwareFoundation.Python.3.10_qbz5n2kfra8p0\LocalCache\local-packages\Python310\site-packages\urllib3\connectionpool.py", line 404, in _make_request self._validate_conn(conn) File "C:\Users\Admin\AppData\Local\Packages\PythonSoftwareFoundation.Python.3.10_qbz5n2kfra8p0\LocalCache\local-packages\Python310\site-packages\urllib3\connectionpool.py", line 1061, in _validate_conn conn.connect() File "C:\Users\Admin\AppData\Local\Packages\PythonSoftwareFoundation.Python.3.10_qbz5n2kfra8p0\LocalCache\local-packages\Python310\site-packages\urllib3\connection.py", line 419, in connect self.sock = ssl_wrap_socket( File "C:\Users\Admin\AppData\Local\Packages\PythonSoftwareFoundation.Python.3.10_qbz5n2kfra8p0\LocalCache\local-packages\Python310\site-packages\urllib3\util\ssl_.py", line 458, in ssl_wrap_socket ssl_sock = _ssl_wrap_socket_impl( File "C:\Users\Admin\AppData\Local\Packages\PythonSoftwareFoundation.Python.3.10_qbz5n2kfra8p0\LocalCache\local-packages\Python310\site-packages\urllib3\util\ssl_.py", line 502, in _ssl_wrap_socket_impl return ssl_context.wrap_socket(sock, server_hostname=server_hostname) File "C:\Program Files\WindowsApps\PythonSoftwareFoundation.Python.3.10_3.10.3056.0_x64__qbz5n2kfra8p0\lib\ssl.py", line 513, in wrap_socket return self.sslsocket_class._create( File "C:\Program Files\WindowsApps\PythonSoftwareFoundation.Python.3.10_3.10.3056.0_x64__qbz5n2kfra8p0\lib\ssl.py", line 1071, in _create self.do_handshake() File "C:\Program Files\WindowsApps\PythonSoftwareFoundation.Python.3.10_3.10.3056.0_x64__qbz5n2kfra8p0\lib\ssl.py", line 1342, in do_handshake self._sslobj.do_handshake() urllib3.exceptions.ProtocolError: ('Connection aborted.', ConnectionResetError(10054, 'An existing connection was forcibly closed by the remote host', None, 10054, None)) During handling of the above exception, another exception occurred: Traceback (most recent call last): File "C:\Users\Admin\trading_desktop_app\trading_ui_connected.py", line 1116, in update_portfolio_data portfolio = n.fetch_wallet_holdings_og(config.address) File "C:\Users\Admin\trading_desktop_app\src\nice_funcs.py", line 555, in fetch_wallet_holdings_og response = requests.get(url, headers=headers) File "C:\Users\Admin\AppData\Local\Packages\PythonSoftwareFoundation.Python.3.10_qbz5n2kfra8p0\LocalCache\local-packages\Python310\site-packages\requests\api.py", line 73, in get return request("get", url, params=params, **kwargs) File "C:\Users\Admin\AppData\Local\Packages\PythonSoftwareFoundation.Python.3.10_qbz5n2kfra8p0\LocalCache\local-packages\Python310\site-packages\requests\api.py", line 59, in request return session.request(method=method, url=url, **kwargs) File "C:\Users\Admin\AppData\Local\Packages\PythonSoftwareFoundation.Python.3.10_qbz5n2kfra8p0\LocalCache\local-packages\Python310\site-packages\requests\sessions.py", line 589, in request resp = self.send(prep, **send_kwargs) File "C:\Users\Admin\AppData\Local\Packages\PythonSoftwareFoundation.Python.3.10_qbz5n2kfra8p0\LocalCache\local-packages\Python310\site-packages\requests\sessions.py", line 703, in send r = adapter.send(request, **kwargs) File "C:\Users\Admin\AppData\Local\Packages\PythonSoftwareFoundation.Python.3.10_qbz5n2kfra8p0\LocalCache\local-packages\Python310\site-packages\requests\adapters.py", line 501, in send raise ConnectionError(err, request=request) requests.exceptions.ConnectionError: ('Connection aborted.', ConnectionResetError(10054, 'An existing connection was forcibly closed by the remote host', None, 10054, None)) 